Workbook

Sheet Cover
B2: iWave SDR Platform - ZU47DR RFSoC
B3: API & Engineering Calculation Reference
B4: Mathematics / DSP | GUI | QDMA & driver | Firmware & PCIe control
B7: Document number | C7: iW-ASCEJ-01-API-Reference-R1.0-REL1.0
B8: Project code | C8: iW-ASCEJ-01
B9: Document revision | C9: R1.0
B10: Package release | C10: REL1.0 (software release 1.2.5)
B11: Package | C11: iW-ASCEJ-01-DF-R1.0-REL1.0
B12: Target device | C12: AMD/Xilinx Zynq UltraScale+ RFSoC xczu47dr-ffvg1517-2-i
B13: Host | C13: x86-64 Linux, Qt 5.15 (Qt 6 supported), iwfg QDMA driver
B14: Date | C14: 05 Oct 2026
B15: Classification | C15: Company confidential - for project use
B16: APIs catalogued | C16: =SUM(Summary!C6:C17) -> 1737
B17: Calculations (live formulas) | C17: =COUNTIF(Calculations!G:G,"Formula") -> 92
B18: Editable inputs | C18: =COUNTIF(Calculations!G:G,"Input") -> 62
B20: Document control
B21: Prepared by
B22: Reviewed by
B23: Approved by
B24: Yellow cells are for the signatories to fill in.
B26: How to use this workbook
B27: • | C27: Contents lists every sheet with a hyperlink and its live row count.
B28: • | C28: Each API sheet has one row per function, method, macro, register, ioctl, struct, constant or GUI signal/slot, with the source file and line in the delivered package (Pkg column: SC = Source Code folder, FF = Firmware Files folder).
B29: • | C29: Use the filter arrows in the header row to search by sub-category, kind or file. Panes are frozen on the header and the API name.
B30: • | C30: Calculations holds every derived number (data rates, capture budget, H2C chunk ladder, register encodings, DAC packing, FFT/ENBW, link budget) as live formulas. Edit the blue-on-yellow inputs to plan a configuration.
B31: • | C31: System Data Path walks the transmit, receive and control chains stage by stage with the APIs involved.
B32: • | C32: Test Coverage maps each automated test to the APIs it exercises and its recorded result in this release.

Sheet Contents
A1: Contents
A2: Click a sheet name to open it. Row counts are live formulas.
A4: # | B4: Sheet | C4: What it contains | D4: Rows
A5: 1 | B5: Summary | C5: Entry counts per sheet, sub-category and kind (live COUNTIF formulas).
A6: 2 | B6: Package Structure | C6: The iW-ASCEJ-01 delivery folder tree: DF > HF, FF, SF > BN, SC, UM, AT, TS - what each folder holds.
A7: 3 | B7: System Data Path | C7: Transmit (host > H2C > DAC), receive (ADC > C2H > GUI) and control (GUI > PCIe mailbox > firmware) chains, stage by stage.
A8: 4 | B8: Calculations | C8: Live engineering calculator: converter rates, register encodings, capture budget, H2C ladder, DAC packing, FFT/ENBW, recording guard, PCIe link, simulator.
A9: 5 | B9: Calc Tables | C9: Window ENBW / coherent-gain table and the H2C chunk step-down ladder (live formulas).
A10: 6 | B10: Math DSP | C10: Every mathematical routine, constant and derived quantity in the host GUI: FFT, windows, spectral metrics (SINAD/SNR/THD/SFDR/ENOB), EVM, DDC/NCO, waveform generation, DAC packing, sample codecs, rate/bandwidth, display scaling, GPU kernels, simulation model, validation. | D10: =COUNTA('Math DSP'!A5:A5000) -> 238
A11: 7 | B11: GUI Qt | C11: Qt widgets, windows, dialogs, plots and their signals/slots: MainWindow, ControlWindow3D (H2C/RFDC window), SourcePanel, plots, dialogs, theme. | D11: =COUNTA('GUI Qt'!A5:A5000) -> 197
A12: 8 | B12: App Core | C12: Application core (non-visual) classes: entry point, BackendLauncher, RfdcControl, IqGenerator, DspEngine, sources, recorder, guards, probes, types. | D12: =COUNTA('App Core'!A5:A5000) -> 303
A13: 9 | B13: Platform Libs | C13: External platform and library APIs the GUI calls: Qt Core/GUI/Widgets, POSIX, Linux tools, CUDA, RDMA/RoCEv2, C/C++ runtime. | D13: =COUNTA('Platform Libs'!A5:A5000) -> 43
A14: 10 | B14: QDMA Driver | C14: iwfg Linux kernel driver (QDMA): ioctls, UAPI structs, file operations, H2C/C2H paths, rings, doorbells, interrupts, DMA-BUF, overflow recovery, QDMA context programming. | D14: =COUNTA('QDMA Driver'!A5:A5000) -> 314
A15: 11 | B15: QDMA Registers | C15: QDMA register map, descriptor formats and PL user registers used by the driver. | D15: =COUNTA('QDMA Registers'!A5:A5000) -> 133
A16: 12 | B16: QDMA Helpers | C16: User-space DMA helpers launched by the GUI: c2h_stream (fifo_pipe.c, capture) and iwfg_h2c (transmit ping-pong / replay / watchdog). | D16: =COUNTA('QDMA Helpers'!A5:A5000) -> 101
A17: 13 | B17: QDMA Host | C17: How the GUI drives QDMA: BackendLauncher (helper lifecycle, ordered stop, reset, step-down, restart) and DmaSource (FIFO reader). | D17: =COUNTA('QDMA Host'!A5:A5000) -> 92
A18: 14 | B18: Firmware | C18: Bare-metal A53 firmware (ZU47DR): init sequence, clocking (LMK04828/LMX2594), RFDC control, calibration, DSA/VOP, Nyquist, MTS, DDS, AXIS routing, DAC source switch, UART menu. | D18: =COUNTA(Firmware!A5:A5000) -> 90
A19: 15 | B19: PCIe Control | C19: PCIe register mailbox (ABI 4): ring_register / RFDC_configuration layout, events, readbacks, error codes, capabilities, defaults, unit conversions, firmware handler. | D19: =COUNTA('PCIe Control'!A5:A5000) -> 103
A20: 16 | B20: Xilinx BSP | C20: Xilinx standalone BSP / driver APIs the firmware calls: XRFdc, XGpio, XAxisScr, calibration, MTS, NCO, DSA/VOP, register access, timing. | D20: =COUNTA('Xilinx BSP'!A5:A5000) -> 59
A21: 17 | B21: Host CLI Client | C21: Host-side control clients of the PCIe mailbox: rfdc_ctl CLI with pcie_access, and the GUI's RfdcControl client. | D21: =COUNTA('Host CLI Client'!A5:A5000) -> 64
A22: 18 | B22: Test Coverage | C22: Automated test suites, the APIs they exercise and their results in REL1.0.
A23: 19 | B23: Glossary | C23: Abbreviations and terms.
A24: 20 | B24: Revision History | C24: Document and package revision record.
C25: Total API entries | D25: =SUM(D5:D24) -> 1737

Sheet Summary
A1: Summary
A2: Counts recalculate from the API sheets (COUNTIF on the Sub-category / Kind columns).
A5: Sheet | B5: Scope | C5: Entries | D5: Share | E5: Sub-categories | F5: Source folders
A6: Math DSP | B6: Every mathematical routine, constant and derived quantity in the host GUI: FFT, windows, spectral metrics (SINAD/SNR/THD/SFDR/ENOB), EVM, DDC/NCO, waveform gene... | C6: =COUNTA('Math DSP'!A5:A5000) -> 238 | D6: =IF($C$18=0,0,C6/$C$18) -> 0.13701785 | E6: 17 | F6: SC
A7: GUI Qt | B7: Qt widgets, windows, dialogs, plots and their signals/slots: MainWindow, ControlWindow3D (H2C/RFDC window), SourcePanel, plots, dialogs, theme. | C7: =COUNTA('GUI Qt'!A5:A5000) -> 197 | D7: =IF($C$18=0,0,C7/$C$18) -> 0.11341393 | E7: 20 | F7: SC
A8: App Core | B8: Application core (non-visual) classes: entry point, BackendLauncher, RfdcControl, IqGenerator, DspEngine, sources, recorder, guards, probes, types. | C8: =COUNTA('App Core'!A5:A5000) -> 303 | D8: =IF($C$18=0,0,C8/$C$18) -> 0.17443869 | E8: 25 | F8: SC
A9: Platform Libs | B9: External platform and library APIs the GUI calls: Qt Core/GUI/Widgets, POSIX, Linux tools, CUDA, RDMA/RoCEv2, C/C++ runtime. | C9: =COUNTA('Platform Libs'!A5:A5000) -> 43 | D9: =IF($C$18=0,0,C9/$C$18) -> 0.024755325 | E9: 8 | F9: SC
A10: QDMA Driver | B10: iwfg Linux kernel driver (QDMA): ioctls, UAPI structs, file operations, H2C/C2H paths, rings, doorbells, interrupts, DMA-BUF, overflow recovery, QDMA context pr... | C10: =COUNTA('QDMA Driver'!A5:A5000) -> 314 | D10: =IF($C$18=0,0,C10/$C$18) -> 0.18077145 | E10: 18 | F10: SC
A11: QDMA Registers | B11: QDMA register map, descriptor formats and PL user registers used by the driver. | C11: =COUNTA('QDMA Registers'!A5:A5000) -> 133 | D11: =IF($C$18=0,0,C11/$C$18) -> 0.076568797 | E11: 3 | F11: SC
A12: QDMA Helpers | B12: User-space DMA helpers launched by the GUI: c2h_stream (fifo_pipe.c, capture) and iwfg_h2c (transmit ping-pong / replay / watchdog). | C12: =COUNTA('QDMA Helpers'!A5:A5000) -> 101 | D12: =IF($C$18=0,0,C12/$C$18) -> 0.058146229 | E12: 2 | F12: SC
A13: QDMA Host | B13: How the GUI drives QDMA: BackendLauncher (helper lifecycle, ordered stop, reset, step-down, restart) and DmaSource (FIFO reader). | C13: =COUNTA('QDMA Host'!A5:A5000) -> 92 | D13: =IF($C$18=0,0,C13/$C$18) -> 0.052964882 | E13: 2 | F13: SC
A14: Firmware | B14: Bare-metal A53 firmware (ZU47DR): init sequence, clocking (LMK04828/LMX2594), RFDC control, calibration, DSA/VOP, Nyquist, MTS, DDS, AXIS routing, DAC source sw... | C14: =COUNTA(Firmware!A5:A5000) -> 90 | D14: =IF($C$18=0,0,C14/$C$18) -> 0.051813472 | E14: 13 | F14: FF
A15: PCIe Control | B15: PCIe register mailbox (ABI 4): ring_register / RFDC_configuration layout, events, readbacks, error codes, capabilities, defaults, unit conversions, firmware han... | C15: =COUNTA('PCIe Control'!A5:A5000) -> 103 | D15: =IF($C$18=0,0,C15/$C$18) -> 0.05929764 | E15: 9 | F15: FF
A16: Xilinx BSP | B16: Xilinx standalone BSP / driver APIs the firmware calls: XRFdc, XGpio, XAxisScr, calibration, MTS, NCO, DSA/VOP, register access, timing. | C16: =COUNTA('Xilinx BSP'!A5:A5000) -> 59 | D16: =IF($C$18=0,0,C16/$C$18) -> 0.033966609 | E16: 11 | F16: FF
A17: Host CLI Client | B17: Host-side control clients of the PCIe mailbox: rfdc_ctl CLI with pcie_access, and the GUI's RfdcControl client. | C17: =COUNTA('Host CLI Client'!A5:A5000) -> 64 | D17: =IF($C$18=0,0,C17/$C$18) -> 0.036845135 | E17: 3 | F17: SC
A18: Total | C18: =SUM(C6:C17) -> 1737 | D18: =SUM(D6:D17) -> 1 | E18: =SUM(E6:E17) -> 131
A21: Entries by sheet and sub-category
A22: Sheet | B22: Sub-category | C22: Entries | D22: Share of sheet
A23: Math DSP | B23: DAC packing | C23: =COUNTIF('Math DSP'!$C$5:$C$242,B23) -> 5 | D23: =IF(COUNTA('Math DSP'!$A$5:$A$242)=0,0,C23/COUNTA('Math DSP'!$A$5:$A$242)) -> 0.021008403
A24: Math DSP | B24: DDC / NCO | C24: =COUNTIF('Math DSP'!$C$5:$C$242,B24) -> 3 | D24: =IF(COUNTA('Math DSP'!$A$5:$A$242)=0,0,C24/COUNTA('Math DSP'!$A$5:$A$242)) -> 0.012605042
A25: Math DSP | B25: Display scaling | C25: =COUNTIF('Math DSP'!$C$5:$C$242,B25) -> 37 | D25: =IF(COUNTA('Math DSP'!$A$5:$A$242)=0,0,C25/COUNTA('Math DSP'!$A$5:$A$242)) -> 0.15546218
A26: Math DSP | B26: FFT | C26: =COUNTIF('Math DSP'!$C$5:$C$242,B26) -> 4 | D26: =IF(COUNTA('Math DSP'!$A$5:$A$242)=0,0,C26/COUNTA('Math DSP'!$A$5:$A$242)) -> 0.016806723
A27: Math DSP | B27: GPU | C27: =COUNTIF('Math DSP'!$C$5:$C$242,B27) -> 16 | D27: =IF(COUNTA('Math DSP'!$A$5:$A$242)=0,0,C27/COUNTA('Math DSP'!$A$5:$A$242)) -> 0.067226891
A28: Math DSP | B28: Loopback verification | C28: =COUNTIF('Math DSP'!$C$5:$C$242,B28) -> 10 | D28: =IF(COUNTA('Math DSP'!$A$5:$A$242)=0,0,C28/COUNTA('Math DSP'!$A$5:$A$242)) -> 0.042016807
A29: Math DSP | B29: Modulation / EVM | C29: =COUNTIF('Math DSP'!$C$5:$C$242,B29) -> 16 | D29: =IF(COUNTA('Math DSP'!$A$5:$A$242)=0,0,C29/COUNTA('Math DSP'!$A$5:$A$242)) -> 0.067226891
A30: Math DSP | B30: Rate & bandwidth | C30: =COUNTIF('Math DSP'!$C$5:$C$242,B30) -> 44 | D30: =IF(COUNTA('Math DSP'!$A$5:$A$242)=0,0,C30/COUNTA('Math DSP'!$A$5:$A$242)) -> 0.18487395
A31: Math DSP | B31: Sample codec | C31: =COUNTIF('Math DSP'!$C$5:$C$242,B31) -> 8 | D31: =IF(COUNTA('Math DSP'!$A$5:$A$242)=0,0,C31/COUNTA('Math DSP'!$A$5:$A$242)) -> 0.033613445
A32: Math DSP | B32: Simulation model | C32: =COUNTIF('Math DSP'!$C$5:$C$242,B32) -> 16 | D32: =IF(COUNTA('Math DSP'!$A$5:$A$242)=0,0,C32/COUNTA('Math DSP'!$A$5:$A$242)) -> 0.067226891
A33: Math DSP | B33: Spectral averaging | C33: =COUNTIF('Math DSP'!$C$5:$C$242,B33) -> 5 | D33: =IF(COUNTA('Math DSP'!$A$5:$A$242)=0,0,C33/COUNTA('Math DSP'!$A$5:$A$242)) -> 0.021008403
A34: Math DSP | B34: Spectral metrics | C34: =COUNTIF('Math DSP'!$C$5:$C$242,B34) -> 24 | D34: =IF(COUNTA('Math DSP'!$A$5:$A$242)=0,0,C34/COUNTA('Math DSP'!$A$5:$A$242)) -> 0.10084034
... A39: Math DSP | B39: Windowing | C39: =COUNTIF('Math DSP'!$C$5:$C$242,B39) -> 12 | D39: =IF(COUNTA('Math DSP'!$A$5:$A$242)=0,0,C39/COUNTA('Math DSP'!$A$5:$A$242)) -> 0.050420168
A40: GUI Qt | B40: BackendModeDialog | C40: =COUNTIF('GUI Qt'!$C$5:$C$201,B40) -> 3 | D40: =IF(COUNTA('GUI Qt'!$A$5:$A$201)=0,0,C40/COUNTA('GUI Qt'!$A$5:$A$201)) -> 0.015228426
A41: GUI Qt | B41: ChannelDialog | C41: =COUNTIF('GUI Qt'!$C$5:$C$201,B41) -> 5 | D41: =IF(COUNTA('GUI Qt'!$A$5:$A$201)=0,0,C41/COUNTA('GUI Qt'!$A$5:$A$201)) -> 0.025380711
A42: GUI Qt | B42: ColorMap | C42: =COUNTIF('GUI Qt'!$C$5:$C$201,B42) -> 5 | D42: =IF(COUNTA('GUI Qt'!$A$5:$A$201)=0,0,C42/COUNTA('GUI Qt'!$A$5:$A$201)) -> 0.025380711
A43: GUI Qt | B43: ConfigDialog | C43: =COUNTIF('GUI Qt'!$C$5:$C$201,B43) -> 10 | D43: =IF(COUNTA('GUI Qt'!$A$5:$A$201)=0,0,C43/COUNTA('GUI Qt'!$A$5:$A$201)) -> 0.050761421
A44: GUI Qt | B44: ConstellationPlot | C44: =COUNTIF('GUI Qt'!$C$5:$C$201,B44) -> 4 | D44: =IF(COUNTA('GUI Qt'!$A$5:$A$201)=0,0,C44/COUNTA('GUI Qt'!$A$5:$A$201)) -> 0.020304569
A45: GUI Qt | B45: ControlWindow3D | C45: =COUNTIF('GUI Qt'!$C$5:$C$201,B45) -> 56 | D45: =IF(COUNTA('GUI Qt'!$A$5:$A$201)=0,0,C45/COUNTA('GUI Qt'!$A$5:$A$201)) -> 0.28426396
A46: GUI Qt | B46: DisplayPanel | C46: =COUNTIF('GUI Qt'!$C$5:$C$201,B46) -> 6 | D46: =IF(COUNTA('GUI Qt'!$A$5:$A$201)=0,0,C46/COUNTA('GUI Qt'!$A$5:$A$201)) -> 0.030456853
A47: GUI Qt | B47: InstrumentPlot | C47: =COUNTIF('GUI Qt'!$C$5:$C$201,B47) -> 5 | D47: =IF(COUNTA('GUI Qt'!$A$5:$A$201)=0,0,C47/COUNTA('GUI Qt'!$A$5:$A$201)) -> 0.025380711
A48: GUI Qt | B48: MainWindow | C48: =COUNTIF('GUI Qt'!$C$5:$C$201,B48) -> 36 | D48: =IF(COUNTA('GUI Qt'!$A$5:$A$201)=0,0,C48/COUNTA('GUI Qt'!$A$5:$A$201)) -> 0.18274112
...

Sheet Package Structure
A1: Package Structure
A2: Folder naming: iW-ASCEJ-01-<code>-R1.0-REL1.0 (R1.0 = document/folder revision, REL1.0 = package release). REL1.0 carries software 1.2.5.
A4: Code | B4: Level | C4: Folder name | D4: Meaning | E4: Contents
A5: DF | B5: 0 | C5: iW-ASCEJ-01-DF-R1.0-REL1.0 | D5: Deliverable Folder - package root | E5: README.md (folder legend, quick start), iW-ASCEJ-01-ReleaseNotes-R1.0-REL1.0 (.md/.pdf), this API workbook, VERSION, MANIFEST.sha256
A6: HF | B6: 1 | C6: iW-ASCEJ-01-HF-R1.0-REL1.0 | D6: Hardware Files | E6: 01_PS_Configuration: psu_init.c / psu_init.html (Zynq MPSoC PS config: clocks, DDR4, MIO, GT lanes). 02_Vitis_Platform: export.json (zu47dr_plat / standalone_domain). 03_PL_Design: list of PL files to be supplied (XSA, bitstream, hwh). Hardware Interface Summary (.md/.pdf).
A7: FF | B7: 1 | C7: iW-ASCEJ-01-FF-R1.0-REL1.0 | D7: Firmware Files | E7: 01_Source: 37 bare-metal C sources/headers (main.c, pcie_cfg.c, pcie_regs.h, rfdc_*.c, adc*.c, cli.c, dac_waves.c ...). 02_Boot: boot.bif, make_boot.sh, boot_probe.tcl, jtag_boot_test.tcl, linker fragment. 03_Documentation: boot/flash/porting/RFDC guides, register header reference. 04_Binaries: where BOOT.BIN / ELF go after the Vitis build.
A8: SF | B8: 1 | C8: iW-ASCEJ-01-SF-R1.0-REL1.0 | D8: Software Files | E8: Host software, split into the five folders below.
A9: BN | B9: 2 | C9: iW-ASCEJ-01-BN-R1.0-REL1.0 | D9: Binaries | E9: 01_Host_x86-64: sdr_workstation (GUI) and rfdc_ctl (CLI), prebuilt on Ubuntu 24.04 (glibc >= 2.38), with SHA-256 sums. Backend helpers are built per host by the GUI build.
A10: SC | B10: 2 | C10: iW-ASCEJ-01-SC-R1.0-REL1.0 | D10: Source Code | E10: 01_sdr_workstation_GUI: Qt GUI (src/core, src/ui), backend helpers (C2H c2h_stream, H2C iwfg_h2c, UDP receiver), iwfg QDMA kernel driver (drivers/), resources, CMake. 02_host_tools: rfdc_ctl + pcie_access.
A11: UM | B11: 2 | C11: iW-ASCEJ-01-UM-R1.0-REL1.0 | D11: User Manual | E11: iW-ASCEJ-01-User-Manual-R1.0-REL1.0.pdf (installation, quick start, operation, RFDC control, transmit/receive, troubleshooting). 01_Reference_Guides: topic guides. 02_Developer_Notes: design notes, root-cause reports, changelog.
A12: AT | B12: 2 | C12: iW-ASCEJ-01-AT-R1.0-REL1.0 | D12: Acceptance Test | E12: iW-ASCEJ-01-ATP-R1.0-REL1.0.pdf (procedure), iW-ASCEJ-01-ATR-R1.0-REL1.0.xlsx (automated results + bench record sheet). 01_Logs: raw logs of every automated test in this release.
A13: TS | B13: 2 | C13: iW-ASCEJ-01-TS-R1.0-REL1.0 | D13: Test Suite | E13: 01_Host_Test_Suite: run_all.sh + firmware, pcie_emu, gui, h2c_emu suites (no board needed). 02_Scripts: verify.sh, audit_sync.sh, make_manifest.sh, inventory.sh, gpu_p2p_check.sh.
A15: Tree
C16: iW-ASCEJ-01-DF-R1.0-REL1.0/ |-- iW-ASCEJ-01-HF-R1.0-REL1.0/ Hardware Files |-- iW-ASCEJ-01-FF-R1.0-REL1.0/ Firmware Files |-- iW-ASCEJ-01-SF-R1.0-REL1.0/ Software Files | |-- iW-ASCEJ-01-BN-R1.0-REL1.0/ Binaries | |-- iW-ASCEJ-01-SC-R1.0-REL1.0/ Source Code | |-- iW-ASCEJ-01-UM-R1.0-REL1.0/ User Manual | |-- iW-ASCEJ-01-AT-R1.0-REL1.0/ Acceptance Test | `-- iW-ASCEJ-01-TS-R1.0-REL1.0/ Test Suite |-- iW-ASCEJ-01-API-Reference-R1.0-REL1.0.xlsx |-- iW-ASCEJ-01-ReleaseNotes-R1.0-REL1.0.pdf |-- README.md VERSION MANIFEST.sha256

Sheet System Data Path
A1: System Data Path
A2: Stage-by-stage view of the three chains with the APIs involved. Rates link live to the Calculations sheet (green).
A4: Chain | B4: Stage | C4: Function | D4: Where it runs | E4: APIs involved | F4: Data / rule | G4: Source
A5: TRANSMIT host > H2C > DAC
A6: TX | B6: 1 | C6: Waveform generation | D6: GUI generator | E6: IqGenerator::renderLoop / fillChunk, Waveform::shape, coherentHz | F6: Loop of N = chunk/4 I/Q pairs, coherent tone k*fs/N | G6: SC GUI src/core/IqGenerator.cpp
A7: TX | B7: 2 | C7: DAC packing | D7: GUI generator | E7: packDac (14-bit << 2), sanitiseChunkBytes | F7: int16 I + int16 Q, bits[1:0] = 0, peak 32764 | G7: SC GUI src/core/IqGenerator.cpp
A8: TX | B8: 3 | C8: FIFO to helper | D8: GUI > named pipe | E8: IqGenerator::streamUntilBroken, writeSilence | F8: Writes the loop once; GR_updates = 0/s when unchanged | G8: SC GUI src/core/IqGenerator.cpp
A9: TX | B9: 4 | C9: H2C helper | D9: iwfg_h2c | E9: ping-pong buffers, replay last chunk, watchdog | F9: One blocking DMA_DATA per chunk; replays until new data | G9: SC GUI backend/H2C/iwfg_h2c.c
A10: TX | B10: 5 | C10: Kernel H2C | D10: iwfg driver /dev/iwfg1 | E10: IWFG_IOCTL_ADD_BUF, IWFG_IOCTL_DMA_DATA, iwfg_xmit_data, iwfg_tx_roll, iwfg_wait_for_tx | F10: Descriptors (<= 256 per batch), 100 ms wait slices, 2 s timeout | G10: SC GUI drivers/iwfg_dma.c
A11: TX | B11: 6 | C11: QDMA H2C > AXIS | D11: FPGA | E11: H2C_CTRL.VID_OUT_SEL, AXIS switch S00 (host) | F11: DDS_H2C_switch: S00 = host H2C_data_in, S01 = DDS (platform_ids.h) | G11: FF 01_Source/main.c (routing)
A12: TX | B12: 7 | C12: RF-DAC | D12: RFSoC | E12: XRFdc NCO / interpolation, clk_wiz_dac 200 MHz | F12: One 32-bit I/Q word per 200 MHz clock = 762.9 MiB/s, no TREADY | G12: FF 01_Source/rfdc_*.c
A13: RECEIVE ADC > C2H > GUI
A14: RX | B14: 1 | C14: RF-ADC + DDC | D14: RFSoC | E14: XRFdc decimation, NCO, DSA, QMC | F14: fs_ADC / decimation per channel (4800/24 = 200 MSPS) | G14: FF 01_Source/rfdc_*.c
A15: RX | B15: 2 | C15: AXIS routing / PL GPIO | D15: FPGA | E15: AXIS routing 0x1237 (ch0=7 ch1=3 ch2=2 ch3=1), PL GPIO mode 1/2/3 | F15: 1, 2 or 4 channels into the C2H stream | G15: FF 01_Source/main.c
A16: RX | B16: 3 | C16: QDMA C2H | D16: iwfg driver /dev/iwfg0 | E16: iwfg_rx_poll, C2H ring (16384 entries), usr_ovf recovery | F16: Overflow > QDMA soft reset (affects H2C) - see DRIVER_OVERFLOW_RECOVERY.md | G16: SC GUI drivers/iwfg_dma.c
A17: RX | B17: 4 | C17: C2H helper | D17: c2h_stream | E17: fifo_pipe.c: 4 x 16 MiB pre-armed buffers | F17: Streams to the capture FIFO | G17: SC GUI backend/C2H/fifo_pipe.c
A18: RX | B18: 5 | C18: Host reader | D18: GUI DmaSource | E18: O_NONBLOCK open, poll, F_SETPIPE_SZ, re-attach | F18: SampleBlock to the DSP thread | G18: SC GUI src/core/Sources.cpp
A19: RX | B19: 6 | C19: DSP | D19: GUI DspEngine | E19: applyDdc, computeSpectrum, computeMetrics, computeConstellation | F19: FFT / windows / metrics / EVM | G19: SC GUI src/core/DspEngine.cpp
A20: RX | B20: 7 | C20: Display | D20: GUI plots | E20: SpectrumPlot, WaterfallPlot, TimeDomainPlot, ConstellationPlot, MeasurementPanel | F20: 30 fps max (minFrameMs 33) | G20: SC GUI src/ui/*
A21: CONTROL GUI / CLI > PCIe mailbox > firmware
A22: CTRL | B22: 1 | C22: User action | D22: GUI RFDC tab / rfdc_ctl | E22: RfdcControl::send..., rfdc_ctl commands | F22: Async (no device I/O on the GUI thread) | G22: SC GUI src/core/RfdcControl.cpp
A23: CTRL | B23: 2 | C23: Mailbox write | D23: BAR 2 | E23: RFDC_configuration (0xAC) payload, then ring_register (0xA8) with NEW_CMD | F23: ring = NEW<<31|TGT<<28|LAST<<27|TILE<<24|CH<<20|EVT | G23: SC host_tools pcie_access.c
A24: CTRL | B24: 3 | C24: Firmware poll | D24: A53 bare-metal | E24: pcie_cfg.c poll / dispatch, XRFdc_* calls | F24: Executes the event on the RFDC / GPIO / switch | G24: FF 01_Source/pcie_cfg.c
A25: CTRL | B25: 4 | C25: Acknowledge | D25: A53 > BAR 2 | E25: RING_ACK_BUILD (0x2A<<24 | err<<20 | evt) | F25: NEW_CMD cleared = ACK; status rides in the same write | G25: FF 01_Source/pcie_regs.h
A26: CTRL | B26: 5 | C26: Readback | D26: BAR 2 | E26: PCIE_RB_REQUEST (0x5242<<16 | id), PCIE_RB_* answers | F26: Still 0x5242xxxx = unanswered | G26: FF 01_Source/pcie_cfg.c
A28: Key rates (live links to Calculations)
C29: DAC demand (MiB/s) | E29: =Calculations!$C$79 -> 762.93945
C30: ADC stream rate per channel (MSPS) | E30: =Calculations!$C$10 -> 200
C31: Capture need at the requested channels (MiB/s) | E31: =Calculations!$C$61 -> 3051.7578
C32: Transmit-guard capture budget (MiB/s) | E32: =Calculations!$C$59 -> 1600
C33: Channels allowed while transmitting | E33: =Calculations!$C$65 -> 2
C34: Host tone resolution at the current chunk (Hz) | E34: =Calculations!$C$83 -> 762.93945
C35: H2C transfer efficiency | E35: =Calculations!$C$91 -> 0.99703336

Sheet Calculations
A1: Engineering Calculations (live formulas)
A2: Every number the firmware, driver and GUI derive, as live Excel formulas tied to the code that computes it. Blue on yellow = input you may edit; black = formula; green = link to another cell. Change an input and the sheet recalculates.
A3: Legend: | B3: Input (edit) | C3: Formula | D3: Link
A5: ID | B5: Parameter | C5: Value | D5: Unit | E5: Formula / rule | F5: Code reference (package folder : file : symbol) | G5: Kind
A6: 1. RF data converter rates (firmware defaults, pcie_regs.h PCIE_DEF_*)
A7: C-001 | B7: ADC sampling rate fs_ADC | C7: 4800 | D7: MSPS | E7: Input. Boot default PCIE_DEF_ADC_FS_MHZ. | F7: FF 01_Source/pcie_regs.h : PCIE_DEF_ADC_FS_MHZ | G7: Input
A8: C-002 | B8: ADC decimation factor | C8: 24 | D8: x | E8: Input. Boot default PCIE_DEF_DECIMATION. | F8: FF 01_Source/pcie_regs.h : PCIE_DEF_DECIMATION | G8: Input
A9: C-003 | B9: Decimation factor accepted by firmware? | C9: =IF(OR($C$8=4,$C$8=5,$C$8=6,$C$8=8,$C$8=10,$C$8=12,$C$8=16,$C$8=20,$C$8=24,$C$8=40),"VALID","INVALID") -> VALID | D9: - | E9: is_valid_adc_factor(): factor in {4,5,6,8,10,12,16,20,24,40} | F9: FF 01_Source/main.c : is_valid_adc_factor | G9: Formula
A10: C-004 | B10: ADC stream rate per channel | C10: =$C$7/$C$8 -> 200 | D10: MSPS | E10: fs_stream = fs_ADC / decimation | F10: FF 01_Source/pcie_cfg.c : PCIE_RB_ADC_STREAM_KHZ | G10: Formula
A11: C-005 | B11: ADC stream readback word (adc_stream_khz) | C11: =ROUND($C$7*1000/$C$8,0) -> 200000 | D11: kHz | E11: (u32)(gsps*1e6/f + 0.5) - what the GUI reads back | F11: FF 01_Source/pcie_cfg.c : PCIE_RB_ADC_STREAM_KHZ | G11: Formula
A12: C-006 | B12: DAC sampling rate fs_DAC | C12: 9600 | D12: MSPS | E12: Input. Boot default PCIE_DEF_DAC_FS_MHZ. | F12: FF 01_Source/pcie_regs.h : PCIE_DEF_DAC_FS_MHZ | G12: Input
A13: C-007 | B13: DAC interpolation factor | C13: 24 | D13: x | E13: Input. Boot default PCIE_DEF_INTERPOLATION. | F13: FF 01_Source/pcie_regs.h : PCIE_DEF_INTERPOLATION | G13: Input
A14: C-008 | B14: DAC stream clock (clk_wiz_dac) | C14: 200 | D14: MHz | E14: Input. Read back as current_dac_stream_clk_mhz; one 32-bit I/Q word per clock. | F14: FF 01_Source/pcie_cfg.c : PCIE_RB_DAC_STREAM_KHZ | G14: Input
A15: C-009 | B15: GUI display decimation | C15: 1 | D15: x | E15: Input. AcqConfig.decimation (default 1). | F15: SC GUI src/core/Types.h : AcqConfig | G15: Input
A16: C-010 | B16: GUI display interpolation | C16: 1 | D16: x | E16: Input. AcqConfig.interpolation (default 1). | F16: SC GUI src/core/Types.h : AcqConfig | G16: Input
A17: C-011 | B17: Display / analysis rate Fs | C17: =$C$10*$C$16/$C$15 -> 200 | D17: MSPS | E17: displayRateHz = sampleRateMsps*1e6*interp/decim | F17: SC GUI src/core/Types.h : AcqConfig::displayRateHz | G17: Formula
A18: C-012 | B18: NCO frequency (ADC and DAC) | C18: 3100 | D18: MHz | E18: Input. Boot default PCIE_DEF_NCO_MHZ. | F18: FF 01_Source/pcie_regs.h : PCIE_DEF_NCO_MHZ | G18: Input
A19: C-013 | B19: Nyquist zone of the NCO frequency at fs_ADC | C19: =INT($C$18/($C$7/2))+1 -> 2 | D19: zone | E19: zone = floor(f / (fs/2)) + 1 (RFSoC convention; firmware accepts 1 or 2) | F19: FF 01_Source/rfdc_nyquistzone.c | G19: Formula
A20: C-014 | B20: Nyquist zone of the NCO frequency at fs_DAC | C20: =INT($C$18/($C$12/2))+1 -> 1 | D20: zone | E20: zone = floor(f / (fs/2)) + 1 | F20: FF 01_Source/rfdc_nyquistzone.c | G20: Formula
A21: 2. PCIe control-register encodings (ring_register 0xA8 / RFDC_configuration 0xAC, BAR 2)
A22: C-015 | B22: NCO payload (EVENT 1): magnitude in kHz | C22: =ROUND(ABS($C$18)*1000,0)+IF($C$18<0,2^31,0) -> 3100000 | D22: u32 | E22: |f| in kHz, bit31 = sign. 4.5 GHz -> 0x0044AA20 (pcie_regs.h example) | F22: FF 01_Source/pcie_regs.h : EVENT 1 | G22: Formula
A23: C-016 | B23: NCO payload, hex | C23: =DEC2HEX($C$22,8) -> 002F4D60 | D23: hex | E23: Display only | G23: Formula
A24: C-017 | B24: NCO decoded back (PCIE_NCO_KHZ_TO_MHZ) | C24: =IF($C$22>=2^31,-1,1)*MOD($C$22,2^31)/1000 -> 3100 | D24: MHz | E24: Must equal the input: proves the conversion is inverse (audit_sync.sh) | F24: FF 01_Source/pcie_regs.h : PCIE_NCO_KHZ_TO_MHZ | G24: Formula
A25: C-018 | B25: DDS tone frequency | C25: 10 | D25: MHz | E25: Input. Boot default PCIE_DEF_DDS_MHZ. | F25: FF 01_Source/pcie_regs.h : PCIE_DEF_DDS_MHZ | G25: Input
A26: C-019 | B26: DDS payload (EVENT 5): Hz | C26: =ROUND($C$25*1000000,0) -> 10000000 | D26: Hz | E26: 10 MHz -> 10000000 -> 0x00989680 (pcie_regs.h example) | F26: FF 01_Source/pcie_regs.h : EVENT 5 | G26: Formula
A27: C-020 | B27: DDS payload, hex | C27: =DEC2HEX($C$26,8) -> 00989680 | D27: hex | G27: Formula
A28: C-021 | B28: ADC DSA attenuation | C28: 0 | D28: dB | E28: Input. 0..27 dB. | F28: FF 01_Source/pcie_regs.h : PCIE_EVT_ADC_DSA | G28: Input
A29: C-022 | B29: DSA payload (dB x 10) | C29: =ROUND($C$28*10,0) -> 0 | D29: dBx10 | E29: payload 0..270 | F29: FF 01_Source/pcie_regs.h : PCIE_EVT_ADC_DSA | G29: Formula
A30: C-023 | B30: DSA payload in range? | C30: =IF(AND($C$29>=0,$C$29<=270),"OK","OUT OF RANGE") -> OK | D30: - | E30: 0 <= payload <= 270 | G30: Formula
A31: C-024 | B31: ADC QMC gain | C31: 1 | D31: - | E31: Input. A read-back of 0.0000 means the QMC gain is zeroed - set 1.0 (1.2.5 check). | F31: FF 01_Source/pcie_regs.h : PCIE_EVT_QMC_GAIN | G31: Input
A32: C-025 | B32: QMC payload (gain x 10000) | C32: =ROUND($C$31*10000,0) -> 10000 | D32: x1e4 | F32: FF 01_Source/pcie_regs.h : PCIE_RB_QMC_GAIN_10000 | G32: Formula
A33: C-026 | B33: DAC VOP output current | C33: 32000 | D33: uA | E33: Input. Boot default PCIE_DEF_DAC_VOP_UA (32 mA). | F33: FF 01_Source/pcie_regs.h : PCIE_DEF_DAC_VOP_UA | G33: Input
A34: C-027 | B34: DAC VOP in mA | C34: =$C$33/1000 -> 32 | D34: mA | G34: Formula
A35: C-028 | B35: ring NEW_CMD bit [31] | C35: 1 | D35: bit | E35: Input. Host writes 1; PS clears it (= the ACK). | F35: FF 01_Source/pcie_regs.h : RING_NEWCMD_MASK | G35: Input
A36: C-029 | B36: ring TARGET [30:28] | C36: 0 | D36: code | E36: Input. 0 ADC, 1 DAC, 2 DDS, 4 ADC+DAC | F36: FF 01_Source/pcie_regs.h : RING_TARGET_MASK | G36: Input
A37: C-030 | B37: ring LAST_TILE [27] | C37: 1 | D37: bit | E37: Input. | F37: FF 01_Source/pcie_regs.h : RING_LASTTILE_MASK | G37: Input
A38: C-031 | B38: ring TILE [26:24] | C38: 0 | D38: code | E38: Input. 0..3 tile, 7 all (4 = back-to-back is rejected) | F38: FF 01_Source/pcie_regs.h : RING_TILE_MASK | G38: Input
A39: C-032 | B39: ring CHANNEL [23:20] | C39: 0 | D39: code | E39: Input. 0 Ch0, 1 Ch1, 2 both | F39: FF 01_Source/pcie_regs.h : RING_CHANNEL_MASK | G39: Input
A40: C-033 | B40: ring EVENT [19:0] | C40: 1 | D40: code | E40: Input. 1 NCO freq ... 0x17 MTS realign | F40: FF 01_Source/pcie_regs.h : PCIE_EVT_* | G40: Input
A41: C-034 | B41: ring_register word | C41: =$C$35*2^31+$C$36*2^28+$C$37*2^27+$C$38*2^24+$C$39*2^20+$C$40 -> 2281701377 | D41: u32 | E41: NEW_CMD<<31 | TARGET<<28 | LAST<<27 | TILE<<24 | CH<<20 | EVENT | F41: FF 01_Source/pcie_regs.h : RING_SET | G41: Formula
...

Sheet Calc Tables
A1: Calculation Tables
A2: Window coefficients (ENBW / coherent gain used by Calculations C-105/C-106) and the H2C chunk step-down ladder. Green cells link to Calculations; blue-on-yellow cells are editable.
A4: A. Windows (cosine-sum coefficients from Fft.h makeWindow) - ENBW and coherent gain, exact for large N
A5: Window | B5: a0 | C5: a1 | D5: a2 | E5: ENBW (bins) | F5: ENBW (dB) | G5: Coherent gain | H5: a3 | I5: a4 | J5: Note
A6: Rectangular | B6: 1 | C6: 0 | D6: 0 | E6: =(B6^2+(C6^2+D6^2+H6^2+I6^2)/2)/B6^2 -> 1 | F6: =10*LOG10(E6) -> 0 | G6: =B6 -> 1 | H6: 0 | I6: 0 | J6: w = 1
A7: Hann | B7: 0.5 | C7: 0.5 | D7: 0 | E7: =(B7^2+(C7^2+D7^2+H7^2+I7^2)/2)/B7^2 -> 1.5 | F7: =10*LOG10(E7) -> 1.7609126 | G7: =B7 -> 0.5 | H7: 0 | I7: 0 | J7: 0.5 - 0.5cos
A8: Hamming | B8: 0.54 | C8: 0.46 | D8: 0 | E8: =(B8^2+(C8^2+D8^2+H8^2+I8^2)/2)/B8^2 -> 1.3628258 | F8: =10*LOG10(E8) -> 1.3444034 | G8: =B8 -> 0.54 | H8: 0 | I8: 0 | J8: 0.54 - 0.46cos
A9: Blackman | B9: 0.42 | C9: 0.5 | D9: 0.08 | E9: =(B9^2+(C9^2+D9^2+H9^2+I9^2)/2)/B9^2 -> 1.7267574 | F9: =10*LOG10(E9) -> 2.3723132 | G9: =B9 -> 0.42 | H9: 0 | I9: 0
A10: Blackman-Harris | B10: 0.35875 | C10: 0.48829 | D10: 0.14128 | E10: =(B10^2+(C10^2+D10^2+H10^2+I10^2)/2)/B10^2 -> 2.0043529 | F10: =10*LOG10(E10) -> 3.019742 | G10: =B10 -> 0.35875 | H10: 0.01168 | I10: 0 | J10: default
A11: Flat-top | B11: 0.21557895 | C11: 0.41663158 | D11: 0.27726316 | E11: =(B11^2+(C11^2+D11^2+H11^2+I11^2)/2)/B11^2 -> 3.7702464 | F11: =10*LOG10(E11) -> 5.7636974 | G11: =B11 -> 0.21557895 | H11: 0.083578947 | I11: 0.006947368 | J11: amplitude-accurate
A12: ENBW = (a0^2 + (a1^2+a2^2+a3^2+a4^2)/2) / a0^2 ; CG = a0. Kaiser (beta 8.6) is not a cosine-sum window: windowEnbw() computes it numerically at run time.
A14: B. H2C chunk step-down ladder (BackendLauncher.h kH2cChunkLadder) - what each rung gives
A15: Rung | B15: Chunk (bytes) | C15: Chunk (KiB) | D15: Pages / transfer | E15: Tone resolution df (Hz) | F15: Play time (ms) | G15: Efficiency | H15: Delivered (MiB/s) | I15: DAC kept fed?
A16: 1 | B16: 16777216 | C16: =B16/1024 -> 16384 | D16: =B16/4096 -> 4096 | E16: =Calculations!$C$78/(B16/Calculations!$C$77) -> 47.683716 | F16: =(B16/Calculations!$C$77)/Calculations!$C$78*1000 -> 20.97152 | G16: =(F16/1000)/((F16/1000)+Calculations!$C$90/1000000) -> 0.99981407 | H16: =Calculations!$C$79*G16 -> 762.7976 | I16: =IF(G16>=0.995,"YES","NO - starves") -> YES
A17: 2 | B17: 4194304 | C17: =B17/1024 -> 4096 | D17: =B17/4096 -> 1024 | E17: =Calculations!$C$78/(B17/Calculations!$C$77) -> 190.73486 | F17: =(B17/Calculations!$C$77)/Calculations!$C$78*1000 -> 5.24288 | G17: =(F17/1000)/((F17/1000)+Calculations!$C$90/1000000) -> 0.99925669 | H17: =Calculations!$C$79*G17 -> 762.37235 | I17: =IF(G17>=0.995,"YES","NO - starves") -> YES
A18: 3 | B18: 1048576 | C18: =B18/1024 -> 1024 | D18: =B18/4096 -> 256 | E18: =Calculations!$C$78/(B18/Calculations!$C$77) -> 762.93945 | F18: =(B18/Calculations!$C$77)/Calculations!$C$78*1000 -> 1.31072 | G18: =(F18/1000)/((F18/1000)+Calculations!$C$90/1000000) -> 0.99703336 | H18: =Calculations!$C$79*G18 -> 760.67609 | I18: =IF(G18>=0.995,"YES","NO - starves") -> YES
A19: 4 | B19: 262144 | C19: =B19/1024 -> 256 | D19: =B19/4096 -> 64 | E19: =Calculations!$C$78/(B19/Calculations!$C$77) -> 3051.7578 | F19: =(B19/Calculations!$C$77)/Calculations!$C$78*1000 -> 0.32768 | G19: =(F19/1000)/((F19/1000)+Calculations!$C$90/1000000) -> 0.98823813 | H19: =Calculations!$C$79*G19 -> 753.96586 | I19: =IF(G19>=0.995,"YES","NO - starves") -> NO - starves
A20: 5 | B20: 65536 | C20: =B20/1024 -> 64 | D20: =B20/4096 -> 16 | E20: =Calculations!$C$78/(B20/Calculations!$C$77) -> 12207.031 | F20: =(B20/Calculations!$C$77)/Calculations!$C$78*1000 -> 0.08192 | G20: =(F20/1000)/((F20/1000)+Calculations!$C$90/1000000) -> 0.95455605 | H20: =Calculations!$C$79*G20 -> 728.26847 | I20: =IF(G20>=0.995,"YES","NO - starves") -> NO - starves
A21: 6 | B21: 16384 | C21: =B21/1024 -> 16 | D21: =B21/4096 -> 4 | E21: =Calculations!$C$78/(B21/Calculations!$C$77) -> 48828.125 | F21: =(B21/Calculations!$C$77)/Calculations!$C$78*1000 -> 0.02048 | G21: =(F21/1000)/((F21/1000)+Calculations!$C$90/1000000) -> 0.84003281 | H21: =Calculations!$C$79*G21 -> 640.89418 | I21: =IF(G21>=0.995,"YES","NO - starves") -> NO - starves
A22: Shaded = default rung (1 MiB, kH2cChunkDefault). 16 MiB (4096 pages) never completed on the bench; 16 KiB starves the DAC (~640 MiB/s, matching the bench). The launcher first reopens at the same size, then steps down.
A23: Per-transfer overhead and DAC demand come from Calculations (C-081, C-070).

Sheet Math DSP
A1: Math DSP - API reference
A2: Every mathematical routine, constant and derived quantity in the host GUI: FFT, windows, spectral metrics (SINAD/SNR/THD/SFDR/ENOB), EVM, DDC/NCO, waveform generation, DAC packing, sample codecs, rate/bandwidth, display scaling, GPU kernels, simulation model, validation.
A3: 238 entries. Source: iW-ASCEJ-01-SF-R1.0-REL1.0/iW-ASCEJ-01-SC-R1.0-REL1.0 and iW-ASCEJ-01-FF-R1.0-REL1.0 of release REL1.0 (1.2.5).
A4: ID | B4: Category | C4: Sub-category | D4: API / symbol | E4: Kind | F4: Signature / definition | G4: Purpose | H4: Inputs / parameters | I4: Outputs / returns | J4: Formula / algorithm | K4: Units | L4: Used by / callers | M4: Notes | N4: Pkg | O4: Source file (in package folder) | P4: Line
A5: MATH-001 | B5: Math & DSP (host GUI) | C5: DAC packing | D5: sdr::kPeak14 | E5: constant | F5: static constexpr double kPeak14 = 8191.0; | G5: Largest magnitude of a signed 14-bit DAC sample. | H5: - | I5: 8191 | J5: 2^13 − 1 = 8191 | K5: LSB (14-bit) | L5: packDac | M5: After <<2 the int16 peak is 32764. | N5: SC | O5: 01_sdr_workstation_GUI/src/core/IqGenerator.cpp | P5: 30
A6: MATH-002 | B6: Math & DSP (host GUI) | C6: DAC packing | D6: sdr::packDac | E6: function | F6: static inline qint16 packDac(double v) | G6: Packs a normalised sample into the DAC wire word: quantise to int14 first, then MSB-align so bits[1:0] are always 00. | H6: v: normalised sample (±1 = full scale). | I6: qint16 DAC word. | J6: i14 = clamp(round(v·8191), −8191, +8191); word = i14 << 2 (range ±32764) | K6: int16 code | L6: fillNoise, renderLoop, fillChunk | M6: Quantising before the shift guarantees bits[1:0] = 00 (fifo_sink_v9 contract). | N6: SC | O6: 01_sdr_workstation_GUI/src/core/IqGenerator.cpp | P6: 32
A7: MATH-003 | B7: Math & DSP (host GUI) | C7: DAC packing | D7: sdr::sanitiseChunkBytes | E7: function | F7: static int sanitiseChunkBytes(int bytes) | G7: Forces the H2C chunk to a multiple of 4 bytes within 1 KiB … 64 MiB. | H7: bytes. | I7: bytes. | J7: b = bytes − (bytes mod 4); b = clamp(b, 1024, 64·1024·1024) | K7: bytes | L7: loopPairsFor, IqGenerator::start | N7: SC | O7: 01_sdr_workstation_GUI/src/core/IqGenerator.cpp | P7: 47
A8: MATH-004 | B8: Math & DSP (host GUI) | C8: DAC packing | D8: sdr::IqGenerator::loopPairsFor | E8: method | F8: int IqGenerator::loopPairsFor(int chunkBytes) | G8: IQ pairs in one H2C chunk (the replay loop length). | H8: chunkBytes. | I8: pairs N. | J8: N = sanitiseChunkBytes(chunkBytes)/4 (one int16 I + int16 Q = 4 B) | K8: samples | L8: transmittedHz, ControlWindow3D::updateGenPreview | M8: 1 MiB → 262144 pairs; 16 KiB → 4096. | N8: SC | O8: 01_sdr_workstation_GUI/src/core/IqGenerator.cpp | P8: 105
A9: MATH-005 | B9: Math & DSP (host GUI) | C9: DAC packing | D9: sdr::IqGenerator::peakInt16 | E9: inline | F9: static constexpr int peakInt16() { return 8191 << 2; } | G9: Peak int16 value actually emitted to the DAC. | H9: - | I9: 32764 | J9: 8191 << 2 = 32764 | K9: int16 code | L9: UI full-scale display | N9: SC | O9: 01_sdr_workstation_GUI/src/core/IqGenerator.h | P9: 103
A10: MATH-006 | B10: Math & DSP (host GUI) | C10: DDC / NCO | D10: DspEngine::processBlock [DDC frequency-axis compensation] | E10: lambda/block | F10: frame.centerFreqHz = m_cfg.acq.centerFreqHz() - m_cfg.acq.ncoFreqMHz * 1e6; | G10: Moves the frequency-axis origin to undo the +f_NCO translation applied by applyDdc, so plots, peak table and metrics report true frequency. | H10: acq.centerFreqGHz (GHz), acq.ncoFreqMHz (MHz). | I10: frame.centerFreqHz (Hz). | J10: f_axis_centre = f_centre − f_NCO; f_RF = f_centre + (f_measured − f_NCO) | K10: Hz | L10: computeMetrics (peakFreqHz), findPeaks, SpectrumPlot/WaterfallPlot X axes | M10: f_NCO in MHz ×1e6. Defaults: centre 0 GHz, NCO 0 MHz → baseband axis. | N10: SC | O10: 01_sdr_workstation_GUI/src/core/DspEngine.cpp | P10: 182
A11: MATH-007 | B11: Math & DSP (host GUI) | C11: DDC / NCO | D11: DspEngine::applyDdc | E11: method | F11: void DspEngine::applyDdc(IQBlock& b, quint64 startSample) const | G11: Digital down-conversion: complex mix of the analysis block by the NCO, with phase derived from the absolute sample index so dropped blocks do not rotate frames. | H11: b: IQ samples (in place); startSample: absolute per-channel index; acq.ncoFreqMHz (MHz); displayRateHz Fs (Hz). | I11: b[n] multiplied by e^(+jφ[n]). | J11: Δφ = 2π·f_NCO/Fs; φ[0] = fmod(Δφ·startSample, 2π); y[n] = x[n]·(cos φ[n] + j·sin φ[n]); φ[n+1] = φ[n] + Δφ, wrapped to (−2π, 2π) | K11: rad | L11: DspEngine::processBlock (per selected channel) | M11: No-op when Fs ≤ 0 or |Δφ| < 1e−12. Shifts the spectrum UP by f_NCO (compensated in frame.centerFreqHz). Phase in double, cos/sin cast to float. | N11: SC | O11: 01_sdr_workstation_GUI/src/core/DspEngine.cpp | P11: 286
A12: MATH-008 | B12: Math & DSP (host GUI) | C12: DDC / NCO | D12: sdr::ui::ControlWindow3D::refreshChain [NCO / RF] | E12: lambda/block | F12: set(m_chNco, tr("DAC NCO %1 MHz → tone at RF %2 MHz · ADC NCO %3 MHz").arg(m_devDacNco, 0, 'f', 3).arg(m_devDacNco + txHz / 1e6, 0, 'f', 3)… | G12: Reports the RF frequency of the transmitted tone from the DAC NCO. | H12: m_devDacNco, m_devAdcNco (MHz), txHz = transmittedHz (Hz). | I12: label. | J12: f_RF[MHz] = f_DACNCO + f_tx/1e6 | K12: MHz | L12: refreshChain | M12: Shown only when both NCOs were read back. | N12: SC | O12: 01_sdr_workstation_GUI/src/ui/ControlWindow3D.cpp | P12: 2157
A13: MATH-009 | B13: Math & DSP (host GUI) | C13: Display scaling | D13: sdr::kMaxTimePoints | E13: constant | F13: constexpr int kMaxTimePoints = 512; | G13: Number of contiguous samples handed to the time-domain plot; sets the scope timebase. | H13: - | I13: 512 | J13: visible window = 512 / Fs (e.g. 2.56 µs at 200 MSPS) | K13: samples | L13: DspEngine::processBlock, time-domain metrics (RMS/PAPR/IQ imbalance) | M13: Contiguous (stride 1) after the trigger point — no decimation of the trace. | N13: SC | O13: 01_sdr_workstation_GUI/src/core/DspEngine.cpp | P13: 27
A14: MATH-010 | B14: Math & DSP (host GUI) | C14: Display scaling | D14: DspEngine::processBlock [time-axis span] | E14: lambda/block | F14: frame.blockSpanSec = frame.displayRateHz > 0.0 ? static_cast<double>(plotted) / frame.displayRateHz : 0.0; | G14: Duration represented by the plotted time slice. | H14: plotted samples (first channel's iq size, else analysisN), displayRateHz (Hz). | I14: frame.blockSpanSec (s). | J14: T = N_plotted / Fs | K14: s | L14: TimeDomainPlot::setFrame (m_spanUs = T·1e6) | M14: 0 if Fs ≤ 0. | N14: SC | O14: 01_sdr_workstation_GUI/src/core/DspEngine.cpp | P14: 273
A15: MATH-011 | B15: Math & DSP (host GUI) | C15: Display scaling | D15: sdr::DisplayConfig | E15: struct | F15: struct DisplayConfig { | G15: Display/analysis parameters that shape FFT, averaging, peak search, waterfall and persistence. | H15: - | I15: Fields with defaults. | J15: Defaults: fftSize 2048, window BlackmanHarris, average Exponential, averageCount 8, averageAlpha 0.35, refreshFps 30, floorDb −130, ceilDb 10, peakSearch true, peakCount 5, peakThreshDb 10, peakExcursionPct 4.0, colorMap 0, waterfallRows 320, persistence true, persistDecay 0.90 | K15: points, dB, dBFS, %, fps | L15: DspEngine, Plots, WaterfallPlot, ConstellationPlot | M15: peakThreshDb is relative to the measured noise floor; peakExcursionPct is min peak separation as % of span. | N15: SC | O15: 01_sdr_workstation_GUI/src/core/Types.h | P15: 272
A16: MATH-012 | B16: Math & DSP (host GUI) | C16: Display scaling | D16: sdr::FrameResult | E16: struct | F16: struct FrameResult { | G16: One processed display frame carrying the axis parameters every plot derives its scale from. | H16: - | I16: channels[], stats, displayRateHz (Hz), centerFreqHz (Hz, NCO-compensated), blockSpanSec (s), sequence | K16: Hz, s | L16: Plots::setFrame, MeasurementPanel, MainWindow::renderPending | N16: SC | O16: 01_sdr_workstation_GUI/src/core/Types.h | P16: 474
A17: MATH-013 | B17: Math & DSP (host GUI) | C17: Display scaling | D17: sdr::ui::ColorMap::rgb | E17: inline | F17: inline QRgb rgb(float t) const | G17: Maps a normalised value to a colour via the 256-entry LUT. | H17: t (clamped to [0, 1]). | I17: QRgb. | J17: index = ⌊clamp(t, 0, 1)·255⌋; colour = LUT[index] | K17: RGB | L17: WaterfallPlot::setFrame, ConstellationPlot::setFrame, colour bar | N17: SC | O17: 01_sdr_workstation_GUI/src/ui/ColorMap.h | P17: 30
A18: MATH-014 | B18: Math & DSP (host GUI) | C18: Display scaling | D18: sdr::ui::ColorMap::build [Jet] | E18: lambda/block | F18: r = std::clamp(1.5f - std::abs(4.0f * t - 3.0f), 0.0f, 1.0f); | G18: Jet colour map LUT. | H18: t = i/255, i = 0..255. | I18: LUT[i]. | J18: r = clamp(1.5 − |4t − 3|), g = clamp(1.5 − |4t − 2|), b = clamp(1.5 − |4t − 1|), each to [0, 1]; channel byte = ⌊c·255⌋ | K18: RGB | L18: ColorMap::build (preset 0, default) | N18: SC | O18: 01_sdr_workstation_GUI/src/ui/ColorMap.h | P18: 46
A19: MATH-015 | B19: Math & DSP (host GUI) | C19: Display scaling | D19: sdr::ui::ColorMap::build [Viridis] | E19: lambda/block | F19: r = std::clamp(0.28f + 0.10f * t + 0.75f * t * t * t, 0.0f, 1.0f); | G19: Polynomial Viridis-like colour map LUT. | H19: t = i/255. | I19: LUT[i]. | J19: r = 0.28 + 0.10t + 0.75t³; g = 0.90t; b = 0.33 + 0.85t − 1.05t²; each clamped to [0, 1] | K19: RGB | L19: ColorMap::build (preset 1) | M19: An approximation, not the matplotlib Viridis table. | N19: SC | O19: 01_sdr_workstation_GUI/src/ui/ColorMap.h | P19: 51
A20: MATH-016 | B20: Math & DSP (host GUI) | C20: Display scaling | D20: sdr::ui::ColorMap::build [Inferno] | E20: lambda/block | F20: r = std::clamp(1.35f * t + 0.05f, 0.0f, 1.0f); | G20: Polynomial Inferno-like colour map LUT. | H20: t = i/255. | I20: LUT[i]. | J20: r = 1.35t + 0.05; g = 1.25t²; b = 0.55·sin(3.14159t) + 0.85t⁴; each clamped to [0, 1] | K20: RGB | L20: ColorMap::build (preset 2) | M20: An approximation, not the matplotlib Inferno table. | N20: SC | O20: 01_sdr_workstation_GUI/src/ui/ColorMap.h | P20: 56
A21: MATH-017 | B21: Math & DSP (host GUI) | C21: Display scaling | D21: sdr::ui::ColorMap::build [Grayscale] | E21: lambda/block | F21: r = g = b = t; | G21: Grayscale LUT. | H21: t = i/255. | I21: LUT[i]. | J21: r = g = b = t | K21: RGB | L21: ColorMap::build (preset 3) | N21: SC | O21: 01_sdr_workstation_GUI/src/ui/ColorMap.h | P21: 61
A22: MATH-018 | B22: Math & DSP (host GUI) | C22: Display scaling | D22: sdr::ui::kTableUpdateMs | E22: constant | F22: constexpr int kTableUpdateMs = 120; // measurement tables need not run at 30 fps | G22: Minimum interval between measurement-table / loopback-peak updates. | H22: - | I22: 120 | J22: ≈ 8.3 updates/s | K22: ms | L22: MainWindow::renderPending → MeasurementPanel, ControlWindow3D::setReceivedPeak | N22: SC | O22: 01_sdr_workstation_GUI/src/ui/MainWindow.cpp | P22: 57
A23: MATH-019 | B23: Math & DSP (host GUI) | C23: Display scaling | D23: sdr::ui::kMinSpan | E23: constant | F23: constexpr double kMinSpan = 1e-12; | G23: Smallest axis span treated as valid in mapping and view sync. | H23: - | I23: 1e−12 | K23: axis units | L23: syncView, setViewX, xToPixel, yToPixel | M23: Degenerate spans are widened to 1.0 in syncView. | N23: SC | O23: 01_sdr_workstation_GUI/src/ui/PlotBase.cpp | P23: 39
A24: MATH-020 | B24: Math & DSP (host GUI) | C24: Display scaling | D24: sdr::ui::PlotBase::xToPixel | E24: method | F24: double PlotBase::xToPixel(double v, const QRect& r) const | G24: Linear data-to-pixel mapping on X. | H24: v (data units), r (plot rect). | I24: pixel x. | J24: px = r.left + (v − x0)/(x1 − x0)·r.width (0 offset if span ≤ 1e−12) | K24: px | L24: all plot drawing, markers, overlays | N24: SC | O24: 01_sdr_workstation_GUI/src/ui/PlotBase.cpp | P24: 135
A25: MATH-021 | B25: Math & DSP (host GUI) | C25: Display scaling | D25: sdr::ui::PlotBase::yToPixel | E25: method | F25: double PlotBase::yToPixel(double v, const QRect& r) const | G25: Linear data-to-pixel mapping on Y, optionally inverted. | H25: v, r. | I25: pixel y. | J25: f = (v − y0)/(y1 − y0); py = yInverted ? r.top + f·r.height : r.bottom − f·r.height | K25: px | L25: all plot drawing | M25: Waterfall uses yInverted = true. | N25: SC | O25: 01_sdr_workstation_GUI/src/ui/PlotBase.cpp | P25: 141
A26: MATH-022 | B26: Math & DSP (host GUI) | C26: Display scaling | D26: sdr::ui::PlotBase::pixelToX | E26: method | F26: double PlotBase::pixelToX(double px, const QRect& r) const | G26: Inverse X mapping for cursor, markers and zoom anchors. | H26: px, r. | I26: data x. | J26: x = x0 + (px − r.left)/r.width·(x1 − x0) | K26: data units | L26: wheelEvent, markers, crosshair, box zoom | M26: Returns x0 if width ≤ 0. | N26: SC | O26: 01_sdr_workstation_GUI/src/ui/PlotBase.cpp | P26: 149
A27: MATH-023 | B27: Math & DSP (host GUI) | C27: Display scaling | D27: sdr::ui::PlotBase::pixelToY | E27: method | F27: double PlotBase::pixelToY(double py, const QRect& r) const | G27: Inverse Y mapping. | H27: py, r. | I27: data y. | J27: f = yInverted ? (py − r.top)/h : (r.bottom − py)/h; y = y0 + f·(y1 − y0) | K27: data units | L27: wheelEvent, crosshair, box zoom | M27: Returns y0 if height ≤ 0. | N27: SC | O27: 01_sdr_workstation_GUI/src/ui/PlotBase.cpp | P27: 155
A28: MATH-024 | B28: Math & DSP (host GUI) | C28: Display scaling | D28: sdr::ui::PlotBase::niceTicks | E28: method | F28: QVector<double> PlotBase::niceTicks(double lo, double hi, int target) | G28: Generates 1-2-5 style 'nice' tick positions for an axis range. | H28: lo, hi, target tick count (X 8, Y 6). | I28: tick values. | J28: raw = (hi − lo)/target; mag = 10^⌊log10 raw⌋; norm = raw/mag; step = mag·(1 if norm < 1.5, 2 if < 3, 5 if < 7, else 10); ticks from ⌈lo/step⌉·step to hi + 1e−6·step | K28: axis units | L28: drawGrid, drawAxes | M28: Values with |v| < 1e−9·step snapped to 0. At most 65 ticks. Empty if hi ≤ lo or target < 2. | N28: SC | O28: 01_sdr_workstation_GUI/src/ui/PlotBase.cpp | P28: 165
A29: MATH-025 | B29: Math & DSP (host GUI) | C29: Display scaling | D29: sdr::ui::PlotBase::formatX | E29: method | F29: QString PlotBase::formatX(double v) const | G29: Axis label precision chosen from the visible span (formatY uses the same rule on Y). | H29: v; view span. | I29: text. | J29: decimals = 0 if span ≥ 100; 1 if ≥ 10; 2 if ≥ 1; else 3 | K29: - | L29: drawAxes, crosshair, marker readout | M29: Overridden by SpectrumPlot/WaterfallPlot to print MHz. | N29: SC | O29: 01_sdr_workstation_GUI/src/ui/PlotBase.cpp | P29: 191
A30: MATH-026 | B30: Math & DSP (host GUI) | C30: Display scaling | D30: sdr::ui::PlotBase::zoomAxis | E30: method | F30: void PlotBase::zoomAxis(double& lo, double& hi, double anchor, double factor) | G30: Zooms one axis about an anchor value, keeping the value under the pointer fixed. | H30: lo, hi, anchor, factor. | I30: lo, hi updated. | J30: span' = clamp((hi − lo)·factor, 1e−9, 1e15); frac = (anchor − lo)/(hi − lo); lo' = anchor − frac·span'; hi' = lo' + span' | K30: axis units | L30: wheelEvent (0.80 in / 1.25 out), zoomAtCentre, context menu | M30: kMinUsableSpan = 1e−9, kMaxUsableSpan = 1e15; no snap-back to data extent. Ignored if current span is non-finite or ≤ 0. | N30: SC | O30: 01_sdr_workstation_GUI/src/ui/PlotBase.cpp | P30: 451
A31: MATH-027 | B31: Math & DSP (host GUI) | C31: Display scaling | D31: sdr::ui::PlotBase::wheelEvent | E31: method | F31: void PlotBase::wheelEvent(QWheelEvent* e) | G31: Mouse-wheel zoom anchored at the cursor. | H31: wheel delta, modifiers, cursor position. | I31: view range. | J31: factor = 0.80 if delta > 0 else 1.25; X zoom unless Ctrl-only; Y zoom with Ctrl or Shift (if supported) | K31: - | L31: user interaction | M31: Each notch scales span by 0.8 / 1.25 (inverse pair). | N31: SC | O31: 01_sdr_workstation_GUI/src/ui/PlotBase.cpp | P31: 475
A32: MATH-028 | B32: Math & DSP (host GUI) | C32: Display scaling | D32: sdr::ui::PlotBase::mouseMoveEvent [pan] | E32: lambda/block | F32: const double dx = dxPix / r.width() * (m_panX1 - m_panX0); | G32: Drag-to-pan converts pixel displacement into axis displacement. | H32: drag Δpx, Δpy, saved view. | I32: view range. | J32: dx = Δpx/width·(x1 − x0); dy = Δpy/height·(y1 − y0); x' = x − dx; y' = y + dy | K32: axis units | L32: user interaction | N32: SC | O32: 01_sdr_workstation_GUI/src/ui/PlotBase.cpp | P32: 555
A33: MATH-029 | B33: Math & DSP (host GUI) | C33: Display scaling | D33: sdr::ui::PlotBase::emitReadout | E33: method | F33: void PlotBase::emitReadout() | G33: Marker readout including the delta between the last two markers. | H33: markers (≤ 4), traceValueAt. | I33: readout text. | J33: Δx = x_b − x_a; Δy = y(x_b) − y(x_a) for the last two markers | K33: axis units (Hz/dB on spectrum, µs on time plot) | L33: MainWindow status/readout | M33: Oldest marker dropped beyond 4 (Ctrl-click or context menu). | N33: SC | O33: 01_sdr_workstation_GUI/src/ui/PlotBase.cpp | P33: 650
A34: MATH-030 | B34: Math & DSP (host GUI) | C34: Display scaling | D34: sdr::ui::TimeDomainPlot::setFrame | E34: method | F34: void TimeDomainPlot::setFrame(const sdr::FrameResult& f) | G34: Loads I/Q traces, sets the time axis and applies a slow AGC to the Y scale. | H34: f.channels[].iq, f.blockSpanSec. | I34: m_spanUs (µs), m_yMax. | J34: spanUs = blockSpanSec·1e6; peak = max(0.1, max|I|, max|Q|); yMax ← 0.85·yMax + 0.15·(1.25·peak) | K34: µs, amplitude | L34: MainWindow::renderPending | M34: Y axis = ±yMax; X axis = 0 … spanUs. | N34: SC | O34: 01_sdr_workstation_GUI/src/ui/Plots.cpp | P34: 53
A35: MATH-031 | B35: Math & DSP (host GUI) | C35: Display scaling | D35: sdr::ui::TimeDomainPlot::traceValueAt | E35: method | F35: bool TimeDomainPlot::traceValueAt(double x, double& yOut) const | G35: Marker value lookup on the time plot (I component of first trace). | H35: x (µs). | I35: yOut (I amplitude). | J35: idx = ⌊clamp(x/spanUs, 0, 1)·(n − 1)⌋; y = Re(iq[idx]) | K35: amplitude | L35: emitReadout, marker crosshair | M35: No interpolation. | N35: SC | O35: 01_sdr_workstation_GUI/src/ui/Plots.cpp | P35: 90
A36: MATH-032 | B36: Math & DSP (host GUI) | C36: Display scaling | D36: sdr::ui::TimeDomainPlot::drawContent | E36: method | F36: void TimeDomainPlot::drawContent(QPainter& p, const QRect& r) | G36: Renders I/Q traces, switching to a per-pixel-column min/max envelope when dense. | H36: traces, view, rect. | I36: painted traces. | J36: step = spanUs/(n − 1); envelope if visible > 2·width; col = ⌊(t_n − x0)·w/(x1 − x0)⌋; per column draw [min, max] (bridged to previous column) | K36: px | L36: PlotBase::paintEvent | M36: Envelope preserves extremes and is O(width). | N36: SC | O36: 01_sdr_workstation_GUI/src/ui/Plots.cpp | P36: 102
A37: MATH-033 | B37: Math & DSP (host GUI) | C37: Display scaling | D37: sdr::ui::SpectrumPlot::formatX | E37: method | F37: QString SpectrumPlot::formatX(double v) const | G37: Spectrum axis labels in MHz with span-dependent precision. | H37: v (Hz). | I37: text (MHz). | J37: label = v/1e6 with decimals 1 if span ≥ 100 MHz, 2 if ≥ 10, 3 if ≥ 1, else 4 | K37: MHz | L37: drawAxes, readouts | M37: WaterfallPlot::formatX is identical. | N37: SC | O37: 01_sdr_workstation_GUI/src/ui/Plots.cpp | P37: 278
A38: MATH-034 | B38: Math & DSP (host GUI) | C38: Display scaling | D38: sdr::ui::SpectrumPlot::traceValueAt | E38: method | F38: bool SpectrumPlot::traceValueAt(double x, double& yOut) const | G38: Marker level lookup on the spectrum. | H38: x (Hz). | I38: yOut (dBFS). | J38: frac = (x − fMin)/(fMax − fMin); idx = ⌊frac·(n − 1)⌋; y = S[idx] | K38: dBFS | L38: emitReadout, marker crosshair | M38: False outside [0, 1]. Consistent with the (n − 1) bin spacing used in drawContent. | N38: SC | O38: 01_sdr_workstation_GUI/src/ui/Plots.cpp | P38: 293
A39: MATH-035 | B39: Math & DSP (host GUI) | C39: Display scaling | D39: sdr::ui::SpectrumPlot::drawContent | E39: method | F39: void SpectrumPlot::drawContent(QPainter& p, const QRect& r) | G39: Draws spectrum traces (max-per-pixel decimation), OBW band, peak markers, noise-floor line and metric box. | H39: traces, metrics, view. | I39: painted plot. | J39: binHz_plot = (fMax − fMin)/(n − 1); visible bins i0 = bin(x0 − binHz), i1 = bin(x1 + binHz); perPx = max(1, (i1 − i0 + 1)/width); vertex = max S over each group at f = fMin + (i + end)/2·binHz_plot | K39: px | L39: PlotBase::paintEvent | M39: Plot places bin k at fMin + k·Fs/(n − 1) whereas DspEngine assigns centre + (k − N/2)·Fs/N; positions differ by up to ≈ half a bin (DC bin drawn at f_c + Fs/(2(n − 1))). Info box shows Peak, Floor, SNR, OBW. | N39: SC | O39: 01_sdr_workstation_GUI/src/ui/Plots.cpp | P39: 306
A40: MATH-036 | B40: Math & DSP (host GUI) | C40: Display scaling | D40: sdr::ui::SpectrumPlot::drawContent [OBW overlay] | E40: lambda/block | F40: const double lo = m_centerHz - m.occupiedBwHz / 2.0; | G40: Shades the occupied bandwidth on the spectrum. | H40: metrics.occupiedBwHz, m_centerHz. | I40: shaded band. | J40: band = [f_c − OBW/2, f_c + OBW/2] | K40: Hz | L40: SpectrumPlot::drawContent | M40: Centred on the frame centre, not on the measured lo/hi bins, so an off-centre signal's band is drawn displaced. | N40: SC | O40: 01_sdr_workstation_GUI/src/ui/Plots.cpp | P40: 381
...

Sheet GUI Qt
A1: GUI Qt - API reference
A2: Qt widgets, windows, dialogs, plots and their signals/slots: MainWindow, ControlWindow3D (H2C/RFDC window), SourcePanel, plots, dialogs, theme.
A3: 197 entries. Source: iW-ASCEJ-01-SF-R1.0-REL1.0/iW-ASCEJ-01-SC-R1.0-REL1.0 and iW-ASCEJ-01-FF-R1.0-REL1.0 of release REL1.0 (1.2.5).
A4: ID | B4: Category | C4: Sub-category | D4: API / symbol | E4: Kind | F4: Signature / definition | G4: Purpose | H4: Inputs / parameters | I4: Outputs / returns | J4: Formula / algorithm | K4: Units | L4: Used by / callers | M4: Notes | N4: Pkg | O4: Source file (in package folder) | P4: Line
A5: GUI-001 | B5: GUI (Qt) | C5: BackendModeDialog | D5: sdr::ui::BackendModeDialog | E5: class | F5: class BackendModeDialog : public QDialog | G5: Modal 'Start Live Acquisition' picker for C2H (capture) or H2C_C2H (playback + capture loopback). | L5: Included by MainWindow.cpp but not instantiated in 1.2.5: startBackendThenAcquire takes the launcher's data-flow choice instead | M5: Header-only. | N5: SC | O5: 01_sdr_workstation_GUI/src/ui/BackendModeDialog.h | P5: 23
A6: GUI-002 | B6: GUI (Qt) | C6: BackendModeDialog | D6: BackendModeDialog::BackendModeDialog | E6: method | F6: explicit BackendModeDialog(sdr::BackendMode current = sdr::BackendMode::C2H, QWidget* parent = nullptr) | G6: Builds the two radio buttons with 'current' pre-selected. | H6: current, parent | M6: Inline. | N6: SC | O6: 01_sdr_workstation_GUI/src/ui/BackendModeDialog.h | P6: 27
A7: GUI-003 | B7: GUI (Qt) | C7: BackendModeDialog | D7: BackendModeDialog::mode | E7: method | F7: sdr::BackendMode mode() const | G7: Selected backend mode. | I7: BackendMode::C2H or H2C_C2H | M7: Inline. | N7: SC | O7: 01_sdr_workstation_GUI/src/ui/BackendModeDialog.h | P7: 69
A8: GUI-004 | B8: GUI (Qt) | C8: ChannelDialog | D8: sdr::ui::ChannelDialog | E8: class | F8: class ChannelDialog : public QDialog | G8: Modal selector for any combination of channels 1..16 (Select All / Clear All; OK disabled when none ticked). | L8: SourcePanel::openChannelDialog | M8: Header-only; layout sized from font metrics. | N8: SC | O8: 01_sdr_workstation_GUI/src/ui/ChannelDialog.h | P8: 26
A9: GUI-005 | B9: GUI (Qt) | C9: ChannelDialog | D9: ChannelDialog::ChannelDialog | E9: method | F9: ChannelDialog(int available, quint32 mask, QWidget* parent = nullptr) | G9: Builds one checkbox per available channel (clamped 1..16) pre-ticked from the mask (0 = all). | H9: available, mask (bit c = channel c), parent | L9: SourcePanel::openChannelDialog | M9: Inline. | N9: SC | O9: 01_sdr_workstation_GUI/src/ui/ChannelDialog.h | P9: 32
A10: GUI-006 | B10: GUI (Qt) | C10: ChannelDialog | D10: ChannelDialog::mask | E10: method | F10: quint32 mask() const | G10: Selected channel bitmask (never 0 from an accepted dialog). | I10: quint32 mask | L10: SourcePanel::openChannelDialog | M10: Inline. | N10: SC | O10: 01_sdr_workstation_GUI/src/ui/ChannelDialog.h | P10: 100
A11: GUI-007 | B11: GUI (Qt) | C11: ChannelDialog | D11: ChannelDialog::label | E11: method | F11: static QString label(quint32 mask, int available) | G11: Compact label for the Source panel, e.g. '1,2,5,8', 'All (16)' or 'None'. | H11: mask, available | I11: QString | L11: SourcePanel::refreshChannelField | M11: Inline, static. | N11: SC | O11: 01_sdr_workstation_GUI/src/ui/ChannelDialog.h | P11: 109
A12: GUI-008 | B12: GUI (Qt) | C12: ChannelDialog | D12: ChannelDialog::refreshSummary | E12: slot | F12: void refreshSummary() | G12: Updates 'n of N selected' and enables OK only when n > 0. | L12: Each checkbox toggled | M12: Inline. | N12: SC | O12: 01_sdr_workstation_GUI/src/ui/ChannelDialog.h | P12: 121
A13: GUI-009 | B13: GUI (Qt) | C13: ColorMap | D13: sdr::ui::ColorMap | E13: class | F13: class ColorMap | G13: 256-entry colour lookup table (Jet, Viridis, Inferno, Grayscale) for waterfall and constellation density. | L13: WaterfallPlot, ConstellationPlot | M13: Header-only, not a QObject. | N13: SC | O13: 01_sdr_workstation_GUI/src/ui/ColorMap.h | P13: 13
A14: GUI-010 | B14: GUI (Qt) | C14: ColorMap | D14: ColorMap::Preset | E14: enum | F14: enum Preset { Jet, Viridis, Inferno, Grayscale }; | G14: Colour map presets (index = DisplayConfig.colorMap). | L14: DisplayPanel colour map combo | N14: SC | O14: 01_sdr_workstation_GUI/src/ui/ColorMap.h | P14: 16
A15: GUI-011 | B15: GUI (Qt) | C15: ColorMap | D15: ColorMap::names | E15: method | F15: static QStringList names() | G15: Display names of the presets. | I15: QStringList | L15: DisplayPanel colour-map combo (Panels.cpp:809) | N15: SC | O15: 01_sdr_workstation_GUI/src/ui/ColorMap.h | P15: 18
A16: GUI-012 | B16: GUI (Qt) | C16: ColorMap | D16: ColorMap::setPreset | E16: method | F16: void setPreset(int i) { build(static_cast<Preset>(std::clamp(i, 0, 3))); } | G16: Rebuilds the LUT for a preset (int overload clamps 0..3; a Preset overload is at line 26). | H16: i | L16: WaterfallPlot/ConstellationPlot::setDisplayConfig | N16: SC | O16: 01_sdr_workstation_GUI/src/ui/ColorMap.h | P16: 27
A17: GUI-013 | B17: GUI (Qt) | C17: ColorMap | D17: ColorMap::rgb | E17: method | F17: inline QRgb rgb(float t) const | G17: Maps t (clamped 0..1) to a colour. | H17: t | I17: QRgb | J17: index = int(clamp(t,0,1)*255) | L17: WaterfallPlot/ConstellationPlot::setFrame | N17: SC | O17: 01_sdr_workstation_GUI/src/ui/ColorMap.h | P17: 30
